{
  "comments": [
    {
      "unresolved": false,
      "key": {
        "uuid": "01db0170_1dd782de",
        "filename": "/PATCHSET_LEVEL",
        "patchSetId": 9
      },
      "lineNbr": 0,
      "author": {
        "id": 17092
      },
      "writtenOn": "2021-02-19T19:14:49Z",
      "side": 1,
      "message": "Looks good. The TryBot failure in x/tools seems to be caused by CL 240608.",
      "revId": "567a2fa59fd718ce00640bae0cb566cfb8f2506a",
      "serverId": "62eb7196-b449-3ce5-99f1-c037f21e1705"
    }
  ]
}